Workbook

Sheet ראשי
A1: מחשבון תמחור מוצרים ומארזים
A3: חומרי גלם | B3: בגיליון זה איספו את כל חומרי הגלם שאתם משתמשים בהם ואת המחיר בו אתם קונים אותם
A4: אריזות | B4: בגיליון זה הזינו את האריזות ואביזרי האריזה בהם אתם משתמשים
A5: עלות ליחידה | B5: עלות ליחידה תחושב על בסיס החומרים הנדרשים לייצור יחידה אחת וכן עלות העבודה הנדרשת
A6: מוצרים | B6: גיליון מוצרים מוגמרים - מחיר יחידה מוגמרת של מוצר אותו אתם עתידים למכור
A7: מארזים | B7: חישוב עלות למארז על בסיס עלות המוצרים המרכיבים אותו ומחיר האריזה

Sheet חומרי גלם
A1: חומר גלם | B1: עלות רכישה | C1: כמות באריזה | D1: יחידת מידה | G1: חזרה לתפריט
A2: פצפוצי אורז | B2: 18.9 | C2: 500 | D2: גרם
A3: שמנת מתוקה 38% | B3: 7.07 | C3: 250 | D3: גרם
A4: שוקולד מריר מהדרין | B4: 325 | C4: 10000 | D4: גרם
A5: שוקולד חלב מהדרין | B5: 375 | C5: 10000 | D5: גרם
A6: שוקולד לבן מהדרין | B6: 375 | C6: 10000 | D6: גרם
A7: מחית קינדר בואנו | B7: 45 | C7: 1000 | D7: גרם
A8: נוטלה | B8: 40 | C8: 1000 | D8: גרם
A9: פררו רושה | B9: 24.9 | C9: 16 | D9: יחידות
A10: אוריאו רגיל | B10: 9.9 | C10: 176 | D10: גרם
A11: אוריאו דאבל | B11: 9.9 | C11: 170 | D11: גרם
A12: לוטוס ביסקוויט | B12: 11.9 | C12: 250 | D12: גרם
A13: קינדר בואנו לבן וחום(שלישייה)39*3 | B13: 12.9 | C13: 6 | D13: יחידות
... A103: דפי טרנספר | B103: 25 | C103: 1 | D103: יחידות

Sheet אריזות
A1: מוצר | B1: עלות | C1: כמות באריזה | D1: מאיפה נקנה | F1: חזרה לתפריט
A2: קופסאות 40/30/8 | B2: 80 | C2: 10 | D2: חתום בנשיקה
A3: קופסא לאינגליש מכסה גבוה | B3: 45 | C3: 10 | D3: חתום בנשיקה
A4: קופסא מלבנית מחולקת 20/11/5 | B4: 45 | C4: 10 | D4: חתום בנשיקה
A5: חלוקה פנימית לקופסא 20/20/5 | B5: 20 | C5: 10 | D5: חתום בנשיקה
A6: קופסא ל6 קאפקייקס כולל במה | B6: 65 | C6: 10 | D6: חתום בנשיקה
A7: קופסא 30/30/11 כולל תחתית פנימית | B7: 80 | C7: 10 | D7: חתום בנשיקה
A8: מנג'טים לקאפקייקס צבעים -קוטר 7 | B8: 10 | C8: 40 | D8: חתום בנשיקה
A9: קריסטליות עיגול - 10 ס"מ | B9: 25 | C9: 10 | D9: הכי מתוק שיש
A10: קריסטליות עיגול - 16 ס"מ | B10: 115 | C10: 50 | D10: הכי מתוק שיש
A11: קופסא 24/24/13 | B11: 45 | C11: 5 | D11: הכי מתוק שיש
A12: קופסא 25/35/7 עם מכסה גבוה 8.5 ס"מ | B12: 45 | C12: 10 | D12: הכי מתוק שיש
A13: קופסא 25/35/7 עם מכסה גבוה + 5 במות 20 קינוחים | B13: 40 | C13: 5 | D13: הכי מתוק שיש
... A36: מסכות | B36: 15 | C36: 10 | D36: סטוקי

Sheet עלות ליחידה
A1: מרכיבים | D1: =ROUNDUP(SUM(Recipe[עלות למתכון]),2) -> #N/A | F1: עבודה | J1: כמות | O1: אריזה | Q1: =SUM(SinglePack[עלות]) -> #N/A | T1: חזרה לתפריט
A2: חומר גלם | B2: כמות במתכון | C2: יחידת מידה | D2: עלות למתכון | F2: שעות עבודה | G2: עלות לשעת עבודה | H2: עלות עבודה | J2: כמות יחידות | K2: עלות ליחידה | O2: מוצר | P2: כמות | Q2: עלות | S2: מחיר כולל ליחדה
C3: =VLOOKUP(Recipe[[#This Row],[חומר גלם]],'חומרי גלם'!A:D,4,0) -> #N/A | D3: =ROUNDUP(Recipe[[#This Row],[כמות במתכון]]*VLOOKUP(Recipe[[#This Row],[חומר גלם]],'חומרי גלם'!A:D,2,0)/VLOOKUP(Recipe[[#This Row],[חומר גלם]],'חומרי גלם'!A:D,3,0),2) -> #N/A | H3: =Work[[#This Row],[עלות לשעת עבודה]]*Work[[#This Row],[שעות עבודה]] -> 0 | K3: חומרים | L3: עבודה | M3: סה"כ | O3: קופסת קאפקייקס 6 תאים | P3: 1 | Q3: =ROUNDUP(VLOOKUP(SinglePack[[#This Row],[מוצר]],אריזות!A:C,2,0)/VLOOKUP(SinglePack[[#This Row],[מוצר]],אריזות!A:C,3,0)*SinglePack[[#This Row],[כמות]],2) -> 5 | S3: =Q1+M4 -> #N/A
C4: =VLOOKUP(Recipe[[#This Row],[חומר גלם]],'חומרי גלם'!A:D,4,0) -> #N/A | D4: =ROUNDUP(Recipe[[#This Row],[כמות במתכון]]*VLOOKUP(Recipe[[#This Row],[חומר גלם]],'חומרי גלם'!A:D,2,0)/VLOOKUP(Recipe[[#This Row],[חומר גלם]],'חומרי גלם'!A:D,3,0),2) -> #N/A | K4: =ROUNDUP(D1/J4,2) -> #N/A | L4: {=ROUNDUP(Work[עלות עבודה]/J4,2)} -> #DIV/0! | M4: =L4+K4 -> #DIV/0! | Q4: =ROUNDUP(VLOOKUP(SinglePack[[#This Row],[מוצר]],אריזות!A:C,2,0)/VLOOKUP(SinglePack[[#This Row],[מוצר]],אריזות!A:C,3,0)*SinglePack[[#This Row],[כמות]],2) -> #N/A
C5: =VLOOKUP(Recipe[[#This Row],[חומר גלם]],'חומרי גלם'!A:D,4,0) -> #N/A | D5: =ROUNDUP(Recipe[[#This Row],[כמות במתכון]]*VLOOKUP(Recipe[[#This Row],[חומר גלם]],'חומרי גלם'!A:D,2,0)/VLOOKUP(Recipe[[#This Row],[חומר גלם]],'חומרי גלם'!A:D,3,0),2) -> #N/A | Q5: =ROUNDUP(VLOOKUP(SinglePack[[#This Row],[מוצר]],אריזות!A:C,2,0)/VLOOKUP(SinglePack[[#This Row],[מוצר]],אריזות!A:C,3,0)*SinglePack[[#This Row],[כמות]],2) -> #N/A

Sheet מוצרים
A1: מוצר | B1: עלות ליחידה | C1: Column1 | D1: Column2 | E1: חזרה לתפריט
A2: עוגיות אמסטרדם | B2: 4.01
A3: עוגיות שוקולד צ'יפס מושחתות | B3: 5.73
A4: חיתוכיות פררו רושה | B4: 120.19
A5: מגולגלות במבה נוגט | B5: 66.74
A6: פרליני שוקולד חמאת בוטנים | B6: 2.16
A7: טריקולד | B7: 191.87
A8: כדורי לואקר | B8: 4.87
A9: כדורי אוריאו | B9: 7.32
A10: עוגיות חמאה פיסטוק | B10: 5.17
A11: כדורי קינדר בואנו | B11: 8.59
A12: עוגיות שלג | B12: 4.1
A13: עוגת ביסקוויטים פיסטוק | B13: 142
... A20: מגולגלות פיסטוק | B20: 40.46
A21: בקלאווה אגוזים | B21: 157.04 | C21: 250
A22: בקלאווה טחינה | B22: 152.81 | C22: 200
A23: קרם ברולה אישי בקופסא | B23: 12.45 | C23: 25 ליח | D23: גדול ב45
A24: עוגת מוס קינדר 16 | B24: 262.58 | C24: 200 נקי | F24: מארז 400
A25: צנצנות מוס אישי | B25: 24.88 | C25: 55 ליח'
A26: מיני מגנום בסיסי | B26: 8.26 | C26: מינ 15 | D26: גדול 20
A27: מיני דונאטס(עדי כהן) | B27: 4.25 | C27: 6 | D27: 20 מינימום | E27: בייגלה אישי 10
A28: מגולגלות קינדר | B28: 35.96
A29: מוס 16 | B29: 274.54
A30: מוס 20 | B30: 276.16
A31: מוס 24 | B31: 278.01
A32: בראוניז MIRMIS | B32: 71.37
A33: עוגת שוקולד שלי | B33: 61.51
A34: עוגת שוקולד בלי ביצים | B34: 58.69
A35: אוזן המן מירי כץ וניל | B35: 1.82
A36: אוזן המן מירי כץ קקאו | B36: 1.86
A37: אוזן המן מירי כץ פיסטוק | B37: 2.08
A38: עוגת שוקולד אישית(גדול) | B38: 7.1
A39: עוגת שוקולד אישית(קטן) | B39: 5.6
... A48: כללי גדול | B48: 30

Sheet מארזים
A1: מוצרים | C1: =SUM(Table6[עלות]) -> 0 | F1: אריזה | H1: =SUM(Table7[עלות]) -> 0 | P1: חזרה לתפריט
A2: מוצר | B2: כמות במארז | C2: עלות | F2: מוצר | G2: כמות | H2: עלות | K2: עלות מארז | L2: =ROUNDUP(H1+C1,2) -> 0

Sheet מארז פורים ענק
A1: מוצרים | C1: =SUM(Table6139149151[עלות]) -> 171.86 | F1: אריזה | H1: =SUM(Table7140150152[עלות]) -> 13.5 | P1: חזרה לתפריט
A2: מוצר | B2: כמות במארז | C2: עלות | F2: מוצר | G2: כמות | H2: עלות | J2: עלות מארז | K2: =ROUNDUP(H1+C1,2) -> 185.36
A3: עוגיות בראוניז פורים | B3: 10 | C3: =VLOOKUP(Table6139149151[[#This Row],[מוצר]],מוצרים!A:B,2,0)*Table6139149151[[#This Row],[כמות במארז]] -> 21.2 | F3: קופסא 24/24/13 | G3: 1 | H3: =ROUNDUP(VLOOKUP(Table7140150152[[#This Row],[מוצר]],אריזות!A:C,2,0)/VLOOKUP(Table7140150152[[#This Row],[מוצר]],אריזות!A:C,3,0)*Table7140150152[[#This Row],[כמות]],2) -> 9
A4: עוגת שוקולד אישית(קטן) | B4: 1 | C4: =VLOOKUP(Table6139149151[[#This Row],[מוצר]],מוצרים!A:B,2,0)*Table6139149151[[#This Row],[כמות במארז]] -> 5.6 | F4: מסכות | G4: 3 | H4: =ROUNDUP(VLOOKUP(Table7140150152[[#This Row],[מוצר]],אריזות!A:C,2,0)/VLOOKUP(Table7140150152[[#This Row],[מוצר]],אריזות!A:C,3,0)*Table7140150152[[#This Row],[כמות]],2) -> 4.5
A5: אלפחורס | B5: 5 | C5: =VLOOKUP(Table6139149151[[#This Row],[מוצר]],מוצרים!A:B,2,0)*Table6139149151[[#This Row],[כמות במארז]] -> 16.15
A6: אוזן המן מירי כץ וניל | B6: 8 | C6: =VLOOKUP(Table6139149151[[#This Row],[מוצר]],מוצרים!A:B,2,0)*Table6139149151[[#This Row],[כמות במארז]] -> 14.56
A7: אוזן המן מירי כץ קקאו | B7: 12 | C7: =VLOOKUP(Table6139149151[[#This Row],[מוצר]],מוצרים!A:B,2,0)*Table6139149151[[#This Row],[כמות במארז]] -> 22.32
A8: נשיקות מרנג | B8: 12 | C8: =VLOOKUP(Table6139149151[[#This Row],[מוצר]],מוצרים!A:B,2,0)*Table6139149151[[#This Row],[כמות במארז]] -> 35.88
A9: אלפחורס קקאו | B9: 6 | C9: =VLOOKUP(Table6139149151[[#This Row],[מוצר]],מוצרים!A:B,2,0)*Table6139149151[[#This Row],[כמות במארז]] -> 21.24
A10: חטיף שוגי | B10: 7 | C10: =VLOOKUP(Table6139149151[[#This Row],[מוצר]],מוצרים!A:B,2,0)*Table6139149151[[#This Row],[כמות במארז]] -> 14.91
A11: כללי בינוני | B11: 1 | C11: =VLOOKUP(Table6139149151[[#This Row],[מוצר]],מוצרים!A:B,2,0)*Table6139149151[[#This Row],[כמות במארז]] -> 20

Sheet מארז פורים לגנים
A1: מוצרים | C1: =SUM(Table6139149[עלות]) -> 32.39 | F1: אריזה | H1: =SUM(Table7140150[עלות]) -> 7 | P1: חזרה לתפריט
A2: מוצר | B2: כמות במארז | C2: עלות | D2: Column1 | F2: מוצר | G2: כמות | H2: עלות | K2: עלות מארז | L2: =ROUNDUP(H1+C1,2) -> 39.39
A3: עוגיות בראוניז פורים | B3: 2 | C3: =VLOOKUP(Table6139149[[#This Row],[מוצר]],מוצרים!A:B,2,0)*Table6139149[[#This Row],[כמות במארז]] -> 4.24 | F3: קופסת עוגה 25/20/25 או 20/20/6 | G3: 1 | H3: =ROUNDUP(VLOOKUP(Table7140150[[#This Row],[מוצר]],אריזות!A:C,2,0)/VLOOKUP(Table7140150[[#This Row],[מוצר]],אריזות!A:C,3,0)*Table7140150[[#This Row],[כמות]],2) -> 5.5 | L3: תשלום-25
A4: עוגת שוקולד אישית(קטן) | B4: 1 | C4: =VLOOKUP(Table6139149[[#This Row],[מוצר]],מוצרים!A:B,2,0)*Table6139149[[#This Row],[כמות במארז]] -> 5.6 | F4: מסכות | G4: 1 | H4: =ROUNDUP(VLOOKUP(Table7140150[[#This Row],[מוצר]],אריזות!A:C,2,0)/VLOOKUP(Table7140150[[#This Row],[מוצר]],אריזות!A:C,3,0)*Table7140150[[#This Row],[כמות]],2) -> 1.5
A5: אלפחורס | B5: 1 | C5: =VLOOKUP(Table6139149[[#This Row],[מוצר]],מוצרים!A:B,2,0)*Table6139149[[#This Row],[כמות במארז]] -> 3.23
A6: אוזן המן מירי כץ וניל | B6: 2 | C6: =VLOOKUP(Table6139149[[#This Row],[מוצר]],מוצרים!A:B,2,0)*Table6139149[[#This Row],[כמות במארז]] -> 3.64
A7: אוזן המן מירי כץ קקאו | B7: 2 | C7: =VLOOKUP(Table6139149[[#This Row],[מוצר]],מוצרים!A:B,2,0)*Table6139149[[#This Row],[כמות במארז]] -> 3.72
A8: נשיקות מרנג | B8: 4 | C8: =VLOOKUP(Table6139149[[#This Row],[מוצר]],מוצרים!A:B,2,0)*Table6139149[[#This Row],[כמות במארז]] -> 11.96 | D8: מתנה

Sheet מארז פורים גדול
A1: מוצרים | C1: =SUM(Table6139[עלות]) -> 143.1 | F1: אריזה | H1: =SUM(Table7140[עלות]) -> 10 | P1: חזרה לתפריט
A2: מוצר | B2: כמות במארז | C2: עלות | F2: מוצר | G2: כמות | H2: עלות | K2: עלות מארז | L2: =ROUNDUP(H1+C1,2) -> 153.1
A3: עוגיות בראוניז פורים | B3: 6 | C3: =VLOOKUP(Table6139[[#This Row],[מוצר]],מוצרים!A:B,2,0)*Table6139[[#This Row],[כמות במארז]] -> 12.72 | F3: קופסת עוגה 25/20/25 או 20/20/6 | G3: 1 | H3: =ROUNDUP(VLOOKUP(Table7140[[#This Row],[מוצר]],אריזות!A:C,2,0)/VLOOKUP(Table7140[[#This Row],[מוצר]],אריזות!A:C,3,0)*Table7140[[#This Row],[כמות]],2) -> 5.5
A4: עוגת שוקולד אישית(גדול) | B4: 1 | C4: =VLOOKUP(Table6139[[#This Row],[מוצר]],מוצרים!A:B,2,0)*Table6139[[#This Row],[כמות במארז]] -> 7.1 | F4: מסכות | G4: 3 | H4: =ROUNDUP(VLOOKUP(Table7140[[#This Row],[מוצר]],אריזות!A:C,2,0)/VLOOKUP(Table7140[[#This Row],[מוצר]],אריזות!A:C,3,0)*Table7140[[#This Row],[כמות]],2) -> 4.5
A5: עוגיות חמאה | B5: 6 | C5: =VLOOKUP(Table6139[[#This Row],[מוצר]],מוצרים!A:B,2,0)*Table6139[[#This Row],[כמות במארז]] -> 18.24
A6: אלפחורס קקאו | B6: 6 | C6: =VLOOKUP(Table6139[[#This Row],[מוצר]],מוצרים!A:B,2,0)*Table6139[[#This Row],[כמות במארז]] -> 21.24
A7: אלפחורס | B7: 8 | C7: =VLOOKUP(Table6139[[#This Row],[מוצר]],מוצרים!A:B,2,0)*Table6139[[#This Row],[כמות במארז]] -> 25.84
A8: אוזן המן מירי כץ וניל | B8: 6 | C8: =VLOOKUP(Table6139[[#This Row],[מוצר]],מוצרים!A:B,2,0)*Table6139[[#This Row],[כמות במארז]] -> 10.92
A9: אוזן המן מירי כץ קקאו | B9: 6 | C9: =VLOOKUP(Table6139[[#This Row],[מוצר]],מוצרים!A:B,2,0)*Table6139[[#This Row],[כמות במארז]] -> 11.16
A10: נשיקות מרנג | B10: 12 | C10: =VLOOKUP(Table6139[[#This Row],[מוצר]],מוצרים!A:B,2,0)*Table6139[[#This Row],[כמות במארז]] -> 35.88

Sheet מארז פורים בינוני עם כיבודיות
A1: מוצרים | C1: =SUM(Table6139141143145147[עלות]) -> 76.06 | F1: אריזה | H1: =SUM(Table7140142144146148[עלות]) -> 13.22 | P1: חזרה לתפריט
A2: מוצר | B2: כמות במארז | C2: עלות | F2: מוצר | G2: כמות | H2: עלות | K2: עלות מארז | L2: =ROUNDUP(H1+C1,2) -> 89.28
A3: עוגיות בראוניז פורים | B3: 8 | C3: =VLOOKUP(Table6139141143145147[[#This Row],[מוצר]],מוצרים!A:B,2,0)*Table6139141143145147[[#This Row],[כמות במארז]] -> 16.96 | F3: מארז קאפקייקס 6 תאים מכסה שקוף | G3: 1 | H3: =ROUNDUP(VLOOKUP(Table7140142144146148[[#This Row],[מוצר]],אריזות!A:C,2,0)/VLOOKUP(Table7140142144146148[[#This Row],[מוצר]],אריזות!A:C,3,0)*Table7140142144146148[[#This Row],[כמות]],2) -> 5.42
A4: אלפחורס | B4: 6 | C4: =VLOOKUP(Table6139141143145147[[#This Row],[מוצר]],מוצרים!A:B,2,0)*Table6139141143145147[[#This Row],[כמות במארז]] -> 19.38 | F4: כיבודיות | G4: 3 | H4: =ROUNDUP(VLOOKUP(Table7140142144146148[[#This Row],[מוצר]],אריזות!A:C,2,0)/VLOOKUP(Table7140142144146148[[#This Row],[מוצר]],אריזות!A:C,3,0)*Table7140142144146148[[#This Row],[כמות]],2) -> 3.3
A5: אוזן המן מירי כץ וניל | B5: 5 | C5: =VLOOKUP(Table6139141143145147[[#This Row],[מוצר]],מוצרים!A:B,2,0)*Table6139141143145147[[#This Row],[כמות במארז]] -> 9.1 | F5: מסכות | G5: 3 | H5: =ROUNDUP(VLOOKUP(Table7140142144146148[[#This Row],[מוצר]],אריזות!A:C,2,0)/VLOOKUP(Table7140142144146148[[#This Row],[מוצר]],אריזות!A:C,3,0)*Table7140142144146148[[#This Row],[כמות]],2) -> 4.5
A6: אוזן המן מירי כץ קקאו | B6: 3 | C6: =VLOOKUP(Table6139141143145147[[#This Row],[מוצר]],מוצרים!A:B,2,0)*Table6139141143145147[[#This Row],[כמות במארז]] -> 5.58
A7: נשיקות מרנג | B7: 6 | C7: =VLOOKUP(Table6139141143145147[[#This Row],[מוצר]],מוצרים!A:B,2,0)*Table6139141143145147[[#This Row],[כמות במארז]] -> 17.94
A8: עוגת שוקולד אישית(גדול) | B8: 1 | C8: =VLOOKUP(Table6139141143145147[[#This Row],[מוצר]],מוצרים!A:B,2,0)*Table6139141143145147[[#This Row],[כמות במארז]] -> 7.1

Sheet מארז פורים בינוני
A1: מוצרים | C1: =SUM(Table6139141143145[עלות]) -> 66.25 | F1: אריזה | H1: =SUM(Table7140142144146[עלות]) -> 11 | P1: חזרה לתפריט
A2: מוצר | B2: כמות במארז | C2: עלות | F2: מוצר | G2: כמות | H2: עלות | K2: עלות מארז | L2: =ROUNDUP(H1+C1,2) -> 77.25
A3: עוגיות בראוניז פורים | B3: 3 | C3: =VLOOKUP(Table6139141143145[[#This Row],[מוצר]],מוצרים!A:B,2,0)*Table6139141143145[[#This Row],[כמות במארז]] -> 6.36 | F3: קופסא ל6 קאפקייקס כולל במה | G3: 1 | H3: =ROUNDUP(VLOOKUP(Table7140142144146[[#This Row],[מוצר]],אריזות!A:C,2,0)/VLOOKUP(Table7140142144146[[#This Row],[מוצר]],אריזות!A:C,3,0)*Table7140142144146[[#This Row],[כמות]],2) -> 6.5
A4: אלפחורס | B4: 2 | C4: =VLOOKUP(Table6139141143145[[#This Row],[מוצר]],מוצרים!A:B,2,0)*Table6139141143145[[#This Row],[כמות במארז]] -> 6.46 | F4: מסכות | G4: 3 | H4: =ROUNDUP(VLOOKUP(Table7140142144146[[#This Row],[מוצר]],אריזות!A:C,2,0)/VLOOKUP(Table7140142144146[[#This Row],[מוצר]],אריזות!A:C,3,0)*Table7140142144146[[#This Row],[כמות]],2) -> 4.5
A5: אוזן המן מירי כץ וניל | B5: 2 | C5: =VLOOKUP(Table6139141143145[[#This Row],[מוצר]],מוצרים!A:B,2,0)*Table6139141143145[[#This Row],[כמות במארז]] -> 3.64
A6: אוזן המן מירי כץ קקאו | B6: 2 | C6: =VLOOKUP(Table6139141143145[[#This Row],[מוצר]],מוצרים!A:B,2,0)*Table6139141143145[[#This Row],[כמות במארז]] -> 3.72
A7: נשיקות מרנג | B7: 11 | C7: =VLOOKUP(Table6139141143145[[#This Row],[מוצר]],מוצרים!A:B,2,0)*Table6139141143145[[#This Row],[כמות במארז]] -> 32.89
A8: עוגיות חמאה | B8: 2 | C8: =VLOOKUP(Table6139141143145[[#This Row],[מוצר]],מוצרים!A:B,2,0)*Table6139141143145[[#This Row],[כמות במארז]] -> 6.08
A9: עוגת שוקולד אישית(גדול) | B9: 1 | C9: =VLOOKUP(Table6139141143145[[#This Row],[מוצר]],מוצרים!A:B,2,0)*Table6139141143145[[#This Row],[כמות במארז]] -> 7.1

Sheet מארז פורים עם כיבודיות
A1: מוצרים | C1: =SUM(Table6139141143[עלות]) -> 87.08 | F1: אריזה | H1: =SUM(Table7140142144[עלות]) -> 10.5 | P1: חזרה לתפריט
A2: מוצר | B2: כמות במארז | C2: עלות | F2: מוצר | G2: כמות | H2: עלות | K2: עלות מארז | L2: =ROUNDUP(H1+C1,2) -> 97.58
A3: עוגיות בראוניז פורים | B3: 6 | C3: =VLOOKUP(Table6139141143[[#This Row],[מוצר]],מוצרים!A:B,2,0)*Table6139141143[[#This Row],[כמות במארז]] -> 12.72 | F3: מארז חלוקה מכסה | G3: 1 | H3: =ROUNDUP(VLOOKUP(Table7140142144[[#This Row],[מוצר]],אריזות!A:C,2,0)/VLOOKUP(Table7140142144[[#This Row],[מוצר]],אריזות!A:C,3,0)*Table7140142144[[#This Row],[כמות]],2) -> 5
A4: אלפחורס קקאו | B4: 3 | C4: =VLOOKUP(Table6139141143[[#This Row],[מוצר]],מוצרים!A:B,2,0)*Table6139141143[[#This Row],[כמות במארז]] -> 10.62 | F4: כיבודיות | G4: 5 | H4: =ROUNDUP(VLOOKUP(Table7140142144[[#This Row],[מוצר]],אריזות!A:C,2,0)/VLOOKUP(Table7140142144[[#This Row],[מוצר]],אריזות!A:C,3,0)*Table7140142144[[#This Row],[כמות]],2) -> 5.5
A5: אלפחורס | B5: 3 | C5: =VLOOKUP(Table6139141143[[#This Row],[מוצר]],מוצרים!A:B,2,0)*Table6139141143[[#This Row],[כמות במארז]] -> 9.69
A6: אוזן המן מירי כץ וניל | B6: 9 | C6: =VLOOKUP(Table6139141143[[#This Row],[מוצר]],מוצרים!A:B,2,0)*Table6139141143[[#This Row],[כמות במארז]] -> 16.38
A7: אוזן המן מירי כץ קקאו | B7: 9 | C7: =VLOOKUP(Table6139141143[[#This Row],[מוצר]],מוצרים!A:B,2,0)*Table6139141143[[#This Row],[כמות במארז]] -> 16.74
A8: נשיקות מרנג | B8: 7 | C8: =VLOOKUP(Table6139141143[[#This Row],[מוצר]],מוצרים!A:B,2,0)*Table6139141143[[#This Row],[כמות במארז]] -> 20.93
A9: עוגיות חמאה | B9: 0 | C9: =VLOOKUP(Table6139141143[[#This Row],[מוצר]],מוצרים!A:B,2,0)*Table6139141143[[#This Row],[כמות במארז]] -> 0

Sheet מארז פורים קטן
A1: מוצרים | C1: =SUM(Table6139141[עלות]) -> 52.96 | F1: אריזה | H1: =SUM(Table7140142[עלות]) -> 6 | P1: חזרה לתפריט
A2: מוצר | B2: כמות במארז | C2: עלות | F2: מוצר | G2: כמות | H2: עלות | K2: עלות מארז | L2: =ROUNDUP(H1+C1,2) -> 58.96
A3: עוגיות בראוניז פורים | B3: 4 | C3: =VLOOKUP(Table6139141[[#This Row],[מוצר]],מוצרים!A:B,2,0)*Table6139141[[#This Row],[כמות במארז]] -> 8.48 | F3: קופסת עוגת בנטו עם חלון וידית | G3: 1 | H3: =ROUNDUP(VLOOKUP(Table7140142[[#This Row],[מוצר]],אריזות!A:C,2,0)/VLOOKUP(Table7140142[[#This Row],[מוצר]],אריזות!A:C,3,0)*Table7140142[[#This Row],[כמות]],2) -> 4.5
A4: אלפחורס קקאו | B4: 3 | C4: =VLOOKUP(Table6139141[[#This Row],[מוצר]],מוצרים!A:B,2,0)*Table6139141[[#This Row],[כמות במארז]] -> 10.62 | F4: מסכות | G4: 1 | H4: =ROUNDUP(VLOOKUP(Table7140142[[#This Row],[מוצר]],אריזות!A:C,2,0)/VLOOKUP(Table7140142[[#This Row],[מוצר]],אריזות!A:C,3,0)*Table7140142[[#This Row],[כמות]],2) -> 1.5
A5: אלפחורס | B5: 3 | C5: =VLOOKUP(Table6139141[[#This Row],[מוצר]],מוצרים!A:B,2,0)*Table6139141[[#This Row],[כמות במארז]] -> 9.69
A6: אוזן המן מירי כץ וניל | B6: 2 | C6: =VLOOKUP(Table6139141[[#This Row],[מוצר]],מוצרים!A:B,2,0)*Table6139141[[#This Row],[כמות במארז]] -> 3.64
A7: אוזן המן מירי כץ קקאו | B7: 3 | C7: =VLOOKUP(Table6139141[[#This Row],[מוצר]],מוצרים!A:B,2,0)*Table6139141[[#This Row],[כמות במארז]] -> 5.58
A8: נשיקות מרנג | B8: 5 | C8: =VLOOKUP(Table6139141[[#This Row],[מוצר]],מוצרים!A:B,2,0)*Table6139141[[#This Row],[כמות במארז]] -> 14.95

Sheet עוגיות חמאה
A1: מרכיבים | D1: =ROUNDUP(SUM(Recipe10161922495255109114117120123126129138[עלות למתכון]),2) -> 25.87 | F1: עבודה | J1: כמות | O1: אריזה | Q1: =SUM(SinglePack12182124515457111113116119122125128137[עלות]) -> 4.5 | T1: חזרה לתפריט
A2: חומר גלם | B2: כמות במתכון | C2: יחידת מידה | D2: עלות למתכון | F2: שעות עבודה | G2: עלות לשעת עבודה | H2: עלות עבודה | J2: כמות יחידות | K2: עלות ליחידה | O2: מוצר | P2: כמות | Q2: עלות | S2: מחיר כולל ליחדה
A3: חמאה תנובה | B3: 200 | C3: =VLOOKUP(Recipe10161922495255109114117120123126129138[[#This Row],[חומר גלם]],'חומרי גלם'!A:D,4,0) -> גרם | D3: =ROUNDUP(Recipe10161922495255109114117120123126129138[[#This Row],[כמות במתכון]]*VLOOKUP(Recipe10161922495255109114117120123126129138[[#This Row],[חומר גלם]],'חומרי גלם'!A:D,2,0)/VLOOKUP(Recipe10161922495255109114117120123126129138[[#This Row],[חומר גלם]],'חומרי גלם'!A:D,3,0),2) -> 9 | F3: 1 | G3: 50 | H3: =Work11172023505356110112115118121124127136[[#This Row],[עלות לשעת עבודה]]*Work11172023505356110112115118121124127136[[#This Row],[שעות עבודה]] -> 50 | K3: חומרים | L3: עבודה | M3: סה"כ | O3: קופסא לאינגליש מכסה גבוה | P3: 1 | Q3: =ROUNDUP(VLOOKUP(SinglePack12182124515457111113116119122125128137[[#This Row],[מוצר]],אריזות!A:C,2,0)/VLOOKUP(SinglePack12182124515457111113116119122125128137[[#This Row],[מוצר]],אריזות!A:C,3,0)*SinglePack12182124515457111113116119122125128137[[#This Row],[כמות]],2) -> 4.5 | S3: =Q1+M4 -> 7.54
A4: אבקת סוכר | B4: 100 | C4: =VLOOKUP(Recipe10161922495255109114117120123126129138[[#This Row],[חומר גלם]],'חומרי גלם'!A:D,4,0) -> גרם | D4: =ROUNDUP(Recipe10161922495255109114117120123126129138[[#This Row],[כמות במתכון]]*VLOOKUP(Recipe10161922495255109114117120123126129138[[#This Row],[חומר גלם]],'חומרי גלם'!A:D,2,0)/VLOOKUP(Recipe10161922495255109114117120123126129138[[#This Row],[חומר גלם]],'חומרי גלם'!A:D,3,0),2) -> 1 | J4: 25 | K4: =ROUNDUP(D1/J4,2) -> 1.04 | L4: {=ROUNDUP(Work11172023505356110112115118121124127136[עלות עבודה]/J4,2)} -> 2 | M4: =L4+K4 -> 3.04
A5: מחית וניל | B5: 5 | C5: =VLOOKUP(Recipe10161922495255109114117120123126129138[[#This Row],[חומר גלם]],'חומרי גלם'!A:D,4,0) -> גרם | D5: =ROUNDUP(Recipe10161922495255109114117120123126129138[[#This Row],[כמות במתכון]]*VLOOKUP(Recipe10161922495255109114117120123126129138[[#This Row],[חומר גלם]],'חומרי גלם'!A:D,2,0)/VLOOKUP(Recipe10161922495255109114117120123126129138[[#This Row],[חומר גלם]],'חומרי גלם'!A:D,3,0),2) -> 5.38
A6: מלח | B6: 0.1 | C6: =VLOOKUP(Recipe10161922495255109114117120123126129138[[#This Row],[חומר גלם]],'חומרי גלם'!A:D,4,0) -> גרם | D6: =ROUNDUP(Recipe10161922495255109114117120123126129138[[#This Row],[כמות במתכון]]*VLOOKUP(Recipe10161922495255109114117120123126129138[[#This Row],[חומר גלם]],'חומרי גלם'!A:D,2,0)/VLOOKUP(Recipe10161922495255109114117120123126129138[[#This Row],[חומר גלם]],'חומרי גלם'!A:D,3,0),2) -> 0.01
A7: קמח לבן מנופה | B7: 220 | C7: =VLOOKUP(Recipe10161922495255109114117120123126129138[[#This Row],[חומר גלם]],'חומרי גלם'!A:D,4,0) -> גרם | D7: =ROUNDUP(Recipe10161922495255109114117120123126129138[[#This Row],[כמות במתכון]]*VLOOKUP(Recipe10161922495255109114117120123126129138[[#This Row],[חומר גלם]],'חומרי גלם'!A:D,2,0)/VLOOKUP(Recipe10161922495255109114117120123126129138[[#This Row],[חומר גלם]],'חומרי גלם'!A:D,3,0),2) -> 1.9
A8: ביצים M | B8: 1 | C8: =VLOOKUP(Recipe10161922495255109114117120123126129138[[#This Row],[חומר גלם]],'חומרי גלם'!A:D,4,0) -> יחידות | D8: =ROUNDUP(Recipe10161922495255109114117120123126129138[[#This Row],[כמות במתכון]]*VLOOKUP(Recipe10161922495255109114117120123126129138[[#This Row],[חומר גלם]],'חומרי גלם'!A:D,2,0)/VLOOKUP(Recipe10161922495255109114117120123126129138[[#This Row],[חומר גלם]],'חומרי גלם'!A:D,3,0),2) -> 1.08
A9: כללי קטן | B9: 0.5 | C9: =VLOOKUP(Recipe10161922495255109114117120123126129138[[#This Row],[חומר גלם]],'חומרי גלם'!A:D,4,0) -> יחידות | D9: =ROUNDUP(Recipe10161922495255109114117120123126129138[[#This Row],[כמות במתכון]]*VLOOKUP(Recipe10161922495255109114117120123126129138[[#This Row],[חומר גלם]],'חומרי גלם'!A:D,2,0)/VLOOKUP(Recipe10161922495255109114117120123126129138[[#This Row],[חומר גלם]],'חומרי גלם'!A:D,3,0),2) -> 7.5
J11: .

Sheet חטיף שוגי
A1: מרכיבים | D1: =ROUNDUP(SUM(Recipe10161922495255109114117120123126129132135[עלות למתכון]),2) -> 27.51 | F1: עבודה | J1: כמות | O1: אריזה | Q1: =SUM(SinglePack12182124515457111113116119122125128131134[עלות]) -> 4.5 | T1: חזרה לתפריט
A2: חומר גלם | B2: כמות במתכון | C2: יחידת מידה | D2: עלות למתכון | F2: שעות עבודה | G2: עלות לשעת עבודה | H2: עלות עבודה | J2: כמות יחידות | K2: עלות ליחידה | O2: מוצר | P2: כמות | Q2: עלות | S2: מחיר כולל ליחדה
A3: שוקולד לבן מהדרין | B3: 400 | C3: =VLOOKUP(Recipe10161922495255109114117120123126129132135[[#This Row],[חומר גלם]],'חומרי גלם'!A:D,4,0) -> גרם | D3: =ROUNDUP(Recipe10161922495255109114117120123126129132135[[#This Row],[כמות במתכון]]*VLOOKUP(Recipe10161922495255109114117120123126129132135[[#This Row],[חומר גלם]],'חומרי גלם'!A:D,2,0)/VLOOKUP(Recipe10161922495255109114117120123126129132135[[#This Row],[חומר גלם]],'חומרי גלם'!A:D,3,0),2) -> 15 | F3: 0.3 | G3: 50 | H3: =Work11172023505356110112115118121124127130133[[#This Row],[עלות לשעת עבודה]]*Work11172023505356110112115118121124127130133[[#This Row],[שעות עבודה]] -> 15 | K3: חומרים | L3: עבודה | M3: סה"כ | O3: קופסא לאינגליש מכסה גבוה | P3: 1 | Q3: =ROUNDUP(VLOOKUP(SinglePack12182124515457111113116119122125128131134[[#This Row],[מוצר]],אריזות!A:C,2,0)/VLOOKUP(SinglePack12182124515457111113116119122125128131134[[#This Row],[מוצר]],אריזות!A:C,3,0)*SinglePack12182124515457111113116119122125128131134[[#This Row],[כמות]],2) -> 4.5 | S3: =Q1+M4 -> 6.63
A4: קורנפלקס אלופים | B4: 200 | C4: =VLOOKUP(Recipe10161922495255109114117120123126129132135[[#This Row],[חומר גלם]],'חומרי גלם'!A:D,4,0) -> גרם | D4: =ROUNDUP(Recipe10161922495255109114117120123126129132135[[#This Row],[כמות במתכון]]*VLOOKUP(Recipe10161922495255109114117120123126129132135[[#This Row],[חומר גלם]],'חומרי גלם'!A:D,2,0)/VLOOKUP(Recipe10161922495255109114117120123126129132135[[#This Row],[חומר גלם]],'חומרי גלם'!A:D,3,0),2) -> 4.71 | J4: 20 | K4: =ROUNDUP(D1/J4,2) -> 1.38 | L4: {=ROUNDUP(Work11172023505356110112115118121124127130133[עלות עבודה]/J4,2)} -> 0.75 | M4: =L4+K4 -> 2.13
A5: שמן | B5: 20 | C5: =VLOOKUP(Recipe10161922495255109114117120123126129132135[[#This Row],[חומר גלם]],'חומרי גלם'!A:D,4,0) -> מיליליטר | D5: =ROUNDUP(Recipe10161922495255109114117120123126129132135[[#This Row],[כמות במתכון]]*VLOOKUP(Recipe10161922495255109114117120123126129132135[[#This Row],[חומר גלם]],'חומרי גלם'!A:D,2,0)/VLOOKUP(Recipe10161922495255109114117120123126129132135[[#This Row],[חומר גלם]],'חומרי גלם'!A:D,3,0),2) -> 0.3
A6: כללי קטן | B6: 0.5 | C6: =VLOOKUP(Recipe10161922495255109114117120123126129132135[[#This Row],[חומר גלם]],'חומרי גלם'!A:D,4,0) -> יחידות | D6: =ROUNDUP(Recipe10161922495255109114117120123126129132135[[#This Row],[כמות במתכון]]*VLOOKUP(Recipe10161922495255109114117120123126129132135[[#This Row],[חומר גלם]],'חומרי גלם'!A:D,2,0)/VLOOKUP(Recipe10161922495255109114117120123126129132135[[#This Row],[חומר גלם]],'חומרי גלם'!A:D,3,0),2) -> 7.5

Sheet עוגיות בראוניג פורים
A1: מרכיבים | D1: =ROUNDUP(SUM(Recipe10161922495255109114117120123126129[עלות למתכון]),2) -> 34.57 | F1: עבודה | J1: כמות | O1: אריזה | Q1: =SUM(SinglePack12182124515457111113116119122125128[עלות]) -> 4.5 | T1: חזרה לתפריט
A2: חומר גלם | B2: כמות במתכון | C2: יחידת מידה | D2: עלות למתכון | F2: שעות עבודה | G2: עלות לשעת עבודה | H2: עלות עבודה | J2: כמות יחידות | K2: עלות ליחידה | O2: מוצר | P2: כמות | Q2: עלות | S2: מחיר כולל ליחדה
A3: חמאה תנובה | B3: 125 | C3: =VLOOKUP(Recipe10161922495255109114117120123126129[[#This Row],[חומר גלם]],'חומרי גלם'!A:D,4,0) -> גרם | D3: =ROUNDUP(Recipe10161922495255109114117120123126129[[#This Row],[כמות במתכון]]*VLOOKUP(Recipe10161922495255109114117120123126129[[#This Row],[חומר גלם]],'חומרי גלם'!A:D,2,0)/VLOOKUP(Recipe10161922495255109114117120123126129[[#This Row],[חומר גלם]],'חומרי גלם'!A:D,3,0),2) -> 5.63 | F3: 1 | G3: 50 | H3: =Work11172023505356110112115118121124127[[#This Row],[עלות לשעת עבודה]]*Work11172023505356110112115118121124127[[#This Row],[שעות עבודה]] -> 50 | K3: חומרים | L3: עבודה | M3: סה"כ | O3: קופסא לאינגליש מכסה גבוה | P3: 1 | Q3: =ROUNDUP(VLOOKUP(SinglePack12182124515457111113116119122125128[[#This Row],[מוצר]],אריזות!A:C,2,0)/VLOOKUP(SinglePack12182124515457111113116119122125128[[#This Row],[מוצר]],אריזות!A:C,3,0)*SinglePack12182124515457111113116119122125128[[#This Row],[כמות]],2) -> 4.5 | S3: =Q1+M4 -> 6.62
A4: שוקולד מריר מהדרין | B4: 220 | C4: =VLOOKUP(Recipe10161922495255109114117120123126129[[#This Row],[חומר גלם]],'חומרי גלם'!A:D,4,0) -> גרם | D4: =ROUNDUP(Recipe10161922495255109114117120123126129[[#This Row],[כמות במתכון]]*VLOOKUP(Recipe10161922495255109114117120123126129[[#This Row],[חומר גלם]],'חומרי גלם'!A:D,2,0)/VLOOKUP(Recipe10161922495255109114117120123126129[[#This Row],[חומר גלם]],'חומרי גלם'!A:D,3,0),2) -> 7.15 | J4: 40 | K4: =ROUNDUP(D1/J4,2) -> 0.87 | L4: {=ROUNDUP(Work11172023505356110112115118121124127[עלות עבודה]/J4,2)} -> 1.25 | M4: =L4+K4 -> 2.12
A5: ביצים L | B5: 2 | C5: =VLOOKUP(Recipe10161922495255109114117120123126129[[#This Row],[חומר גלם]],'חומרי גלם'!A:D,4,0) -> יחידות | D5: =ROUNDUP(Recipe10161922495255109114117120123126129[[#This Row],[כמות במתכון]]*VLOOKUP(Recipe10161922495255109114117120123126129[[#This Row],[חומר גלם]],'חומרי גלם'!A:D,2,0)/VLOOKUP(Recipe10161922495255109114117120123126129[[#This Row],[חומר גלם]],'חומרי גלם'!A:D,3,0),2) -> 2.33
A6: סוכר לבן | B6: 80 | C6: =VLOOKUP(Recipe10161922495255109114117120123126129[[#This Row],[חומר גלם]],'חומרי גלם'!A:D,4,0) -> גרם | D6: =ROUNDUP(Recipe10161922495255109114117120123126129[[#This Row],[כמות במתכון]]*VLOOKUP(Recipe10161922495255109114117120123126129[[#This Row],[חומר גלם]],'חומרי גלם'!A:D,2,0)/VLOOKUP(Recipe10161922495255109114117120123126129[[#This Row],[חומר גלם]],'חומרי גלם'!A:D,3,0),2) -> 0.42
A7: סוכר חום דמררה | B7: 90 | C7: =VLOOKUP(Recipe10161922495255109114117120123126129[[#This Row],[חומר גלם]],'חומרי גלם'!A:D,4,0) -> גרם | D7: =ROUNDUP(Recipe10161922495255109114117120123126129[[#This Row],[כמות במתכון]]*VLOOKUP(Recipe10161922495255109114117120123126129[[#This Row],[חומר גלם]],'חומרי גלם'!A:D,2,0)/VLOOKUP(Recipe10161922495255109114117120123126129[[#This Row],[חומר גלם]],'חומרי גלם'!A:D,3,0),2) -> 1.17
A8: קקאו | B8: 20 | C8: =VLOOKUP(Recipe10161922495255109114117120123126129[[#This Row],[חומר גלם]],'חומרי גלם'!A:D,4,0) -> גרם | D8: =ROUNDUP(Recipe10161922495255109114117120123126129[[#This Row],[כמות במתכון]]*VLOOKUP(Recipe10161922495255109114117120123126129[[#This Row],[חומר גלם]],'חומרי גלם'!A:D,2,0)/VLOOKUP(Recipe10161922495255109114117120123126129[[#This Row],[חומר גלם]],'חומרי גלם'!A:D,3,0),2) -> 0.87
A9: קורנפלור | B9: 130 | C9: =VLOOKUP(Recipe10161922495255109114117120123126129[[#This Row],[חומר גלם]],'חומרי גלם'!A:D,4,0) -> גרם | D9: =ROUNDUP(Recipe10161922495255109114117120123126129[[#This Row],[כמות במתכון]]*VLOOKUP(Recipe10161922495255109114117120123126129[[#This Row],[חומר גלם]],'חומרי גלם'!A:D,2,0)/VLOOKUP(Recipe10161922495255109114117120123126129[[#This Row],[חומר גלם]],'חומרי גלם'!A:D,3,0),2) -> 1.8
A10: כללי קטן | B10: 1 | C10: =VLOOKUP(Recipe10161922495255109114117120123126129[[#This Row],[חומר גלם]],'חומרי גלם'!A:D,4,0) -> יחידות | D10: =ROUNDUP(Recipe10161922495255109114117120123126129[[#This Row],[כמות במתכון]]*VLOOKUP(Recipe10161922495255109114117120123126129[[#This Row],[חומר גלם]],'חומרי גלם'!A:D,2,0)/VLOOKUP(Recipe10161922495255109114117120123126129[[#This Row],[חומר גלם]],'חומרי גלם'!A:D,3,0),2) -> 15
A11: מלח | B11: 3 | C11: =VLOOKUP(Recipe10161922495255109114117120123126129[[#This Row],[חומר גלם]],'חומרי גלם'!A:D,4,0) -> גרם | D11: =ROUNDUP(Recipe10161922495255109114117120123126129[[#This Row],[כמות במתכון]]*VLOOKUP(Recipe10161922495255109114117120123126129[[#This Row],[חומר גלם]],'חומרי גלם'!A:D,2,0)/VLOOKUP(Recipe10161922495255109114117120123126129[[#This Row],[חומר גלם]],'חומרי גלם'!A:D,3,0),2) -> 0.01
A12: אבקת אפייה | B12: 10 | C12: =VLOOKUP(Recipe10161922495255109114117120123126129[[#This Row],[חומר גלם]],'חומרי גלם'!A:D,4,0) -> גרם | D12: =ROUNDUP(Recipe10161922495255109114117120123126129[[#This Row],[כמות במתכון]]*VLOOKUP(Recipe10161922495255109114117120123126129[[#This Row],[חומר גלם]],'חומרי גלם'!A:D,2,0)/VLOOKUP(Recipe10161922495255109114117120123126129[[#This Row],[חומר גלם]],'חומרי גלם'!A:D,3,0),2) -> 0.19

Sheet נשיקות מרנג
A1: מרכיבים | D1: =ROUNDUP(SUM(Recipe10161922495255109114117120123126129132[עלות למתכון]),2) -> 138.94 | F1: עבודה | J1: כמות | O1: אריזה | Q1: =SUM(SinglePack12182124515457111113116119122125128131[עלות]) -> 4.5 | T1: חזרה לתפריט
A2: חומר גלם | B2: כמות במתכון | C2: יחידת מידה | D2: עלות למתכון | F2: שעות עבודה | G2: עלות לשעת עבודה | H2: עלות עבודה | J2: כמות יחידות | K2: עלות ליחידה | O2: מוצר | P2: כמות | Q2: עלות | S2: מחיר כולל ליחדה
A3: ביצים L | B3: 6 | C3: =VLOOKUP(Recipe10161922495255109114117120123126129132[[#This Row],[חומר גלם]],'חומרי גלם'!A:D,4,0) -> יחידות | D3: =ROUNDUP(Recipe10161922495255109114117120123126129132[[#This Row],[כמות במתכון]]*VLOOKUP(Recipe10161922495255109114117120123126129132[[#This Row],[חומר גלם]],'חומרי גלם'!A:D,2,0)/VLOOKUP(Recipe10161922495255109114117120123126129132[[#This Row],[חומר גלם]],'חומרי גלם'!A:D,3,0),2) -> 6.99 | F3: 2 | G3: 50 | H3: =Work11172023505356110112115118121124127130[[#This Row],[עלות לשעת עבודה]]*Work11172023505356110112115118121124127130[[#This Row],[שעות עבודה]] -> 100 | K3: חומרים | L3: עבודה | M3: סה"כ | O3: קופסא לאינגליש מכסה גבוה | P3: 1 | Q3: =ROUNDUP(VLOOKUP(SinglePack12182124515457111113116119122125128131[[#This Row],[מוצר]],אריזות!A:C,2,0)/VLOOKUP(SinglePack12182124515457111113116119122125128131[[#This Row],[מוצר]],אריזות!A:C,3,0)*SinglePack12182124515457111113116119122125128131[[#This Row],[כמות]],2) -> 4.5 | S3: =Q1+M4 -> 7.49
A4: סוכר לבן | B4: 300 | C4: =VLOOKUP(Recipe10161922495255109114117120123126129132[[#This Row],[חומר גלם]],'חומרי גלם'!A:D,4,0) -> גרם | D4: =ROUNDUP(Recipe10161922495255109114117120123126129132[[#This Row],[כמות במתכון]]*VLOOKUP(Recipe10161922495255109114117120123126129132[[#This Row],[חומר גלם]],'חומרי גלם'!A:D,2,0)/VLOOKUP(Recipe10161922495255109114117120123126129132[[#This Row],[חומר גלם]],'חומרי גלם'!A:D,3,0),2) -> 1.56 | J4: 80 | K4: =ROUNDUP(D1/J4,2) -> 1.74 | L4: {=ROUNDUP(Work11172023505356110112115118121124127130[עלות עבודה]/J4,2)} -> 1.25 | M4: =L4+K4 -> 2.99
A5: מחית וניל | B5: 5 | C5: =VLOOKUP(Recipe10161922495255109114117120123126129132[[#This Row],[חומר גלם]],'חומרי גלם'!A:D,4,0) -> גרם | D5: =ROUNDUP(Recipe10161922495255109114117120123126129132[[#This Row],[כמות במתכון]]*VLOOKUP(Recipe10161922495255109114117120123126129132[[#This Row],[חומר גלם]],'חומרי גלם'!A:D,2,0)/VLOOKUP(Recipe10161922495255109114117120123126129132[[#This Row],[חומר גלם]],'חומרי גלם'!A:D,3,0),2) -> 5.38
A6: מלח | B6: 0.1 | C6: =VLOOKUP(Recipe10161922495255109114117120123126129132[[#This Row],[חומר גלם]],'חומרי גלם'!A:D,4,0) -> גרם | D6: =ROUNDUP(Recipe10161922495255109114117120123126129132[[#This Row],[כמות במתכון]]*VLOOKUP(Recipe10161922495255109114117120123126129132[[#This Row],[חומר גלם]],'חומרי גלם'!A:D,2,0)/VLOOKUP(Recipe10161922495255109114117120123126129132[[#This Row],[חומר גלם]],'חומרי גלם'!A:D,3,0),2) -> 0.01
A7: דפי טרנספר | B7: 5 | C7: =VLOOKUP(Recipe10161922495255109114117120123126129132[[#This Row],[חומר גלם]],'חומרי גלם'!A:D,4,0) -> יחידות | D7: =ROUNDUP(Recipe10161922495255109114117120123126129132[[#This Row],[כמות במתכון]]*VLOOKUP(Recipe10161922495255109114117120123126129132[[#This Row],[חומר גלם]],'חומרי גלם'!A:D,2,0)/VLOOKUP(Recipe10161922495255109114117120123126129132[[#This Row],[חומר גלם]],'חומרי גלם'!A:D,3,0),2) -> 125

Sheet אלפחורס קקאו
A1: מרכיבים | D1: =ROUNDUP(SUM(Recipe10161922495255109114117120123126[עלות למתכון]),2) -> 41.45 | F1: עבודה | J1: כמות | O1: אריזה | Q1: =SUM(SinglePack12182124515457111113116119122125[עלות]) -> 4.5 | T1: חזרה לתפריט
A2: חומר גלם | B2: כמות במתכון | C2: יחידת מידה | D2: עלות למתכון | F2: שעות עבודה | G2: עלות לשעת עבודה | H2: עלות עבודה | J2: כמות יחידות | K2: עלות ליחידה | O2: מוצר | P2: כמות | Q2: עלות | S2: מחיר כולל ליחדה
A3: אבקת סוכר | B3: 50 | C3: =VLOOKUP(Recipe10161922495255109114117120123126[[#This Row],[חומר גלם]],'חומרי גלם'!A:D,4,0) -> גרם | D3: =ROUNDUP(Recipe10161922495255109114117120123126[[#This Row],[כמות במתכון]]*VLOOKUP(Recipe10161922495255109114117120123126[[#This Row],[חומר גלם]],'חומרי גלם'!A:D,2,0)/VLOOKUP(Recipe10161922495255109114117120123126[[#This Row],[חומר גלם]],'חומרי גלם'!A:D,3,0),2) -> 0.5 | F3: 2 | G3: 50 | H3: =Work11172023505356110112115118121124[[#This Row],[עלות לשעת עבודה]]*Work11172023505356110112115118121124[[#This Row],[שעות עבודה]] -> 100 | K3: חומרים | L3: עבודה | M3: סה"כ | O3: קופסא לאינגליש מכסה גבוה | P3: 1 | Q3: =ROUNDUP(VLOOKUP(SinglePack12182124515457111113116119122125[[#This Row],[מוצר]],אריזות!A:C,2,0)/VLOOKUP(SinglePack12182124515457111113116119122125[[#This Row],[מוצר]],אריזות!A:C,3,0)*SinglePack12182124515457111113116119122125[[#This Row],[כמות]],2) -> 4.5 | S3: =Q1+M4 -> 8.04
A4: ביצים M | B4: 1 | C4: =VLOOKUP(Recipe10161922495255109114117120123126[[#This Row],[חומר גלם]],'חומרי גלם'!A:D,4,0) -> יחידות | D4: =ROUNDUP(Recipe10161922495255109114117120123126[[#This Row],[כמות במתכון]]*VLOOKUP(Recipe10161922495255109114117120123126[[#This Row],[חומר גלם]],'חומרי גלם'!A:D,2,0)/VLOOKUP(Recipe10161922495255109114117120123126[[#This Row],[חומר גלם]],'חומרי גלם'!A:D,3,0),2) -> 1.08 | J4: 40 | K4: =ROUNDUP(D1/J4,2) -> 1.04 | L4: {=ROUNDUP(Work11172023505356110112115118121124[עלות עבודה]/J4,2)} -> 2.5 | M4: =L4+K4 -> 3.54
A5: קמח לבן מנופה | B5: 135 | C5: =VLOOKUP(Recipe10161922495255109114117120123126[[#This Row],[חומר גלם]],'חומרי גלם'!A:D,4,0) -> גרם | D5: =ROUNDUP(Recipe10161922495255109114117120123126[[#This Row],[כמות במתכון]]*VLOOKUP(Recipe10161922495255109114117120123126[[#This Row],[חומר גלם]],'חומרי גלם'!A:D,2,0)/VLOOKUP(Recipe10161922495255109114117120123126[[#This Row],[חומר גלם]],'חומרי גלם'!A:D,3,0),2) -> 1.17
A6: קורנפלור | B6: 90 | C6: =VLOOKUP(Recipe10161922495255109114117120123126[[#This Row],[חומר גלם]],'חומרי גלם'!A:D,4,0) -> גרם | D6: =ROUNDUP(Recipe10161922495255109114117120123126[[#This Row],[כמות במתכון]]*VLOOKUP(Recipe10161922495255109114117120123126[[#This Row],[חומר גלם]],'חומרי גלם'!A:D,2,0)/VLOOKUP(Recipe10161922495255109114117120123126[[#This Row],[חומר גלם]],'חומרי גלם'!A:D,3,0),2) -> 1.25
A7: אבקת אפייה | B7: 5 | C7: =VLOOKUP(Recipe10161922495255109114117120123126[[#This Row],[חומר גלם]],'חומרי גלם'!A:D,4,0) -> גרם | D7: =ROUNDUP(Recipe10161922495255109114117120123126[[#This Row],[כמות במתכון]]*VLOOKUP(Recipe10161922495255109114117120123126[[#This Row],[חומר גלם]],'חומרי גלם'!A:D,2,0)/VLOOKUP(Recipe10161922495255109114117120123126[[#This Row],[חומר גלם]],'חומרי גלם'!A:D,3,0),2) -> 0.1
A8: נוטלה | B8: 500 | C8: =VLOOKUP(Recipe10161922495255109114117120123126[[#This Row],[חומר גלם]],'חומרי גלם'!A:D,4,0) -> גרם | D8: =ROUNDUP(Recipe10161922495255109114117120123126[[#This Row],[כמות במתכון]]*VLOOKUP(Recipe10161922495255109114117120123126[[#This Row],[חומר גלם]],'חומרי גלם'!A:D,2,0)/VLOOKUP(Recipe10161922495255109114117120123126[[#This Row],[חומר גלם]],'חומרי גלם'!A:D,3,0),2) -> 20
A9: אגוזי לוז קצוצים | B9: 200 | C9: =VLOOKUP(Recipe10161922495255109114117120123126[[#This Row],[חומר גלם]],'חומרי גלם'!A:D,4,0) -> גרם | D9: =ROUNDUP(Recipe10161922495255109114117120123126[[#This Row],[כמות במתכון]]*VLOOKUP(Recipe10161922495255109114117120123126[[#This Row],[חומר גלם]],'חומרי גלם'!A:D,2,0)/VLOOKUP(Recipe10161922495255109114117120123126[[#This Row],[חומר גלם]],'חומרי גלם'!A:D,3,0),2) -> 11.98
A10: חמאה תנובה | B10: 100 | C10: =VLOOKUP(Recipe10161922495255109114117120123126[[#This Row],[חומר גלם]],'חומרי גלם'!A:D,4,0) -> גרם | D10: =ROUNDUP(Recipe10161922495255109114117120123126[[#This Row],[כמות במתכון]]*VLOOKUP(Recipe10161922495255109114117120123126[[#This Row],[חומר גלם]],'חומרי גלם'!A:D,2,0)/VLOOKUP(Recipe10161922495255109114117120123126[[#This Row],[חומר גלם]],'חומרי גלם'!A:D,3,0),2) -> 4.5
A11: קקאו | B11: 20 | C11: =VLOOKUP(Recipe10161922495255109114117120123126[[#This Row],[חומר גלם]],'חומרי גלם'!A:D,4,0) -> גרם | D11: =ROUNDUP(Recipe10161922495255109114117120123126[[#This Row],[כמות במתכון]]*VLOOKUP(Recipe10161922495255109114117120123126[[#This Row],[חומר גלם]],'חומרי גלם'!A:D,2,0)/VLOOKUP(Recipe10161922495255109114117120123126[[#This Row],[חומר גלם]],'חומרי גלם'!A:D,3,0),2) -> 0.87

Sheet אלפחורס
A1: מרכיבים | D1: =ROUNDUP(SUM(Recipe10161922495255109114117120123[עלות למתכון]),2) -> 28.87 | F1: עבודה | J1: כמות | O1: אריזה | Q1: =SUM(SinglePack12182124515457111113116119122[עלות]) -> 4.5 | T1: חזרה לתפריט
A2: חומר גלם | B2: כמות במתכון | C2: יחידת מידה | D2: עלות למתכון | F2: שעות עבודה | G2: עלות לשעת עבודה | H2: עלות עבודה | J2: כמות יחידות | K2: עלות ליחידה | O2: מוצר | P2: כמות | Q2: עלות | S2: מחיר כולל ליחדה
A3: אבקת סוכר | B3: 50 | C3: =VLOOKUP(Recipe10161922495255109114117120123[[#This Row],[חומר גלם]],'חומרי גלם'!A:D,4,0) -> גרם | D3: =ROUNDUP(Recipe10161922495255109114117120123[[#This Row],[כמות במתכון]]*VLOOKUP(Recipe10161922495255109114117120123[[#This Row],[חומר גלם]],'חומרי גלם'!A:D,2,0)/VLOOKUP(Recipe10161922495255109114117120123[[#This Row],[חומר גלם]],'חומרי גלם'!A:D,3,0),2) -> 0.5 | F3: 2 | G3: 50 | H3: =Work11172023505356110112115118121[[#This Row],[עלות לשעת עבודה]]*Work11172023505356110112115118121[[#This Row],[שעות עבודה]] -> 100 | K3: חומרים | L3: עבודה | M3: סה"כ | O3: קופסא לאינגליש מכסה גבוה | P3: 1 | Q3: =ROUNDUP(VLOOKUP(SinglePack12182124515457111113116119122[[#This Row],[מוצר]],אריזות!A:C,2,0)/VLOOKUP(SinglePack12182124515457111113116119122[[#This Row],[מוצר]],אריזות!A:C,3,0)*SinglePack12182124515457111113116119122[[#This Row],[כמות]],2) -> 4.5 | S3: =Q1+M4 -> 7.73
A4: ביצים M | B4: 1 | C4: =VLOOKUP(Recipe10161922495255109114117120123[[#This Row],[חומר גלם]],'חומרי גלם'!A:D,4,0) -> יחידות | D4: =ROUNDUP(Recipe10161922495255109114117120123[[#This Row],[כמות במתכון]]*VLOOKUP(Recipe10161922495255109114117120123[[#This Row],[חומר גלם]],'חומרי גלם'!A:D,2,0)/VLOOKUP(Recipe10161922495255109114117120123[[#This Row],[חומר גלם]],'חומרי גלם'!A:D,3,0),2) -> 1.08 | J4: 40 | K4: =ROUNDUP(D1/J4,2) -> 0.73 | L4: {=ROUNDUP(Work11172023505356110112115118121[עלות עבודה]/J4,2)} -> 2.5 | M4: =L4+K4 -> 3.23
A5: קמח לבן מנופה | B5: 155 | C5: =VLOOKUP(Recipe10161922495255109114117120123[[#This Row],[חומר גלם]],'חומרי גלם'!A:D,4,0) -> גרם | D5: =ROUNDUP(Recipe10161922495255109114117120123[[#This Row],[כמות במתכון]]*VLOOKUP(Recipe10161922495255109114117120123[[#This Row],[חומר גלם]],'חומרי גלם'!A:D,2,0)/VLOOKUP(Recipe10161922495255109114117120123[[#This Row],[חומר גלם]],'חומרי גלם'!A:D,3,0),2) -> 1.34
A6: קורנפלור | B6: 90 | C6: =VLOOKUP(Recipe10161922495255109114117120123[[#This Row],[חומר גלם]],'חומרי גלם'!A:D,4,0) -> גרם | D6: =ROUNDUP(Recipe10161922495255109114117120123[[#This Row],[כמות במתכון]]*VLOOKUP(Recipe10161922495255109114117120123[[#This Row],[חומר גלם]],'חומרי גלם'!A:D,2,0)/VLOOKUP(Recipe10161922495255109114117120123[[#This Row],[חומר גלם]],'חומרי גלם'!A:D,3,0),2) -> 1.25
A7: אבקת אפייה | B7: 5 | C7: =VLOOKUP(Recipe10161922495255109114117120123[[#This Row],[חומר גלם]],'חומרי גלם'!A:D,4,0) -> גרם | D7: =ROUNDUP(Recipe10161922495255109114117120123[[#This Row],[כמות במתכון]]*VLOOKUP(Recipe10161922495255109114117120123[[#This Row],[חומר גלם]],'חומרי גלם'!A:D,2,0)/VLOOKUP(Recipe10161922495255109114117120123[[#This Row],[חומר גלם]],'חומרי גלם'!A:D,3,0),2) -> 0.1
A8: ריבת חלב קומידה | B8: 500 | C8: =VLOOKUP(Recipe10161922495255109114117120123[[#This Row],[חומר גלם]],'חומרי גלם'!A:D,4,0) -> גרם | D8: =ROUNDUP(Recipe10161922495255109114117120123[[#This Row],[כמות במתכון]]*VLOOKUP(Recipe10161922495255109114117120123[[#This Row],[חומר גלם]],'חומרי גלם'!A:D,2,0)/VLOOKUP(Recipe10161922495255109114117120123[[#This Row],[חומר גלם]],'חומרי גלם'!A:D,3,0),2) -> 15.9
A9: קוקוס | B9: 150 | C9: =VLOOKUP(Recipe10161922495255109114117120123[[#This Row],[חומר גלם]],'חומרי גלם'!A:D,4,0) -> גרם | D9: =ROUNDUP(Recipe10161922495255109114117120123[[#This Row],[כמות במתכון]]*VLOOKUP(Recipe10161922495255109114117120123[[#This Row],[חומר גלם]],'חומרי גלם'!A:D,2,0)/VLOOKUP(Recipe10161922495255109114117120123[[#This Row],[חומר גלם]],'חומרי גלם'!A:D,3,0),2) -> 4.2
A10: חמאה תנובה | B10: 100 | C10: =VLOOKUP(Recipe10161922495255109114117120123[[#This Row],[חומר גלם]],'חומרי גלם'!A:D,4,0) -> גרם | D10: =ROUNDUP(Recipe10161922495255109114117120123[[#This Row],[כמות במתכון]]*VLOOKUP(Recipe10161922495255109114117120123[[#This Row],[חומר גלם]],'חומרי גלם'!A:D,2,0)/VLOOKUP(Recipe10161922495255109114117120123[[#This Row],[חומר גלם]],'חומרי גלם'!A:D,3,0),2) -> 4.5

Sheet עוגת שוקולד אישית
A1: מרכיבים | D1: =ROUNDUP(SUM(Recipe10161922495255109114117120[עלות למתכון]),2) -> 35.91 | F1: עבודה | J1: כמות | O1: אריזה | Q1: =SUM(SinglePack12182124515457111113116119[עלות]) -> 4.5 | T1: חזרה לתפריט
A2: חומר גלם | B2: כמות במתכון | C2: יחידת מידה | D2: עלות למתכון | F2: שעות עבודה | G2: עלות לשעת עבודה | H2: עלות עבודה | J2: כמות יחידות | K2: עלות ליחידה | O2: מוצר | P2: כמות | Q2: עלות | S2: מחיר כולל ליחדה
A3: סוכר לבן | B3: 240 | C3: =VLOOKUP(Recipe10161922495255109114117120[[#This Row],[חומר גלם]],'חומרי גלם'!A:D,4,0) -> גרם | D3: =ROUNDUP(Recipe10161922495255109114117120[[#This Row],[כמות במתכון]]*VLOOKUP(Recipe10161922495255109114117120[[#This Row],[חומר גלם]],'חומרי גלם'!A:D,2,0)/VLOOKUP(Recipe10161922495255109114117120[[#This Row],[חומר גלם]],'חומרי גלם'!A:D,3,0),2) -> 1.25 | F3: 0.4 | G3: 50 | H3: =Work11172023505356110112115118[[#This Row],[עלות לשעת עבודה]]*Work11172023505356110112115118[[#This Row],[שעות עבודה]] -> 20 | K3: חומרים | L3: עבודה | M3: סה"כ | O3: קופסא לאינגליש מכסה גבוה | P3: 1 | Q3: =ROUNDUP(VLOOKUP(SinglePack12182124515457111113116119[[#This Row],[מוצר]],אריזות!A:C,2,0)/VLOOKUP(SinglePack12182124515457111113116119[[#This Row],[מוצר]],אריזות!A:C,3,0)*SinglePack12182124515457111113116119[[#This Row],[כמות]],2) -> 4.5 | S3: =Q1+M4 -> 10.1
A4: ביצים M | B4: 4 | C4: =VLOOKUP(Recipe10161922495255109114117120[[#This Row],[חומר גלם]],'חומרי גלם'!A:D,4,0) -> יחידות | D4: =ROUNDUP(Recipe10161922495255109114117120[[#This Row],[כמות במתכון]]*VLOOKUP(Recipe10161922495255109114117120[[#This Row],[חומר גלם]],'חומרי גלם'!A:D,2,0)/VLOOKUP(Recipe10161922495255109114117120[[#This Row],[חומר גלם]],'חומרי גלם'!A:D,3,0),2) -> 4.3 | J4: 10 | K4: =ROUNDUP(D1/J4,2) -> 3.6 | L4: {=ROUNDUP(Work11172023505356110112115118[עלות עבודה]/J4,2)} -> 2 | M4: =L4+K4 -> 5.6
A5: קמח תופח | B5: 140 | C5: =VLOOKUP(Recipe10161922495255109114117120[[#This Row],[חומר גלם]],'חומרי גלם'!A:D,4,0) -> גרם | D5: =ROUNDUP(Recipe10161922495255109114117120[[#This Row],[כמות במתכון]]*VLOOKUP(Recipe10161922495255109114117120[[#This Row],[חומר גלם]],'חומרי גלם'!A:D,2,0)/VLOOKUP(Recipe10161922495255109114117120[[#This Row],[חומר גלם]],'חומרי גלם'!A:D,3,0),2) -> 1.11
A6: שמן | B6: 200 | C6: =VLOOKUP(Recipe10161922495255109114117120[[#This Row],[חומר גלם]],'חומרי גלם'!A:D,4,0) -> מיליליטר | D6: =ROUNDUP(Recipe10161922495255109114117120[[#This Row],[כמות במתכון]]*VLOOKUP(Recipe10161922495255109114117120[[#This Row],[חומר גלם]],'חומרי גלם'!A:D,2,0)/VLOOKUP(Recipe10161922495255109114117120[[#This Row],[חומר גלם]],'חומרי גלם'!A:D,3,0),2) -> 2.98
A7: שוקולית | B7: 140 | C7: =VLOOKUP(Recipe10161922495255109114117120[[#This Row],[חומר גלם]],'חומרי גלם'!A:D,4,0) -> גרם | D7: =ROUNDUP(Recipe10161922495255109114117120[[#This Row],[כמות במתכון]]*VLOOKUP(Recipe10161922495255109114117120[[#This Row],[חומר גלם]],'חומרי גלם'!A:D,2,0)/VLOOKUP(Recipe10161922495255109114117120[[#This Row],[חומר גלם]],'חומרי גלם'!A:D,3,0),2) -> 4.2
A8: שמנת מתוקה 38% | B8: 250 | C8: =VLOOKUP(Recipe10161922495255109114117120[[#This Row],[חומר גלם]],'חומרי גלם'!A:D,4,0) -> גרם | D8: =ROUNDUP(Recipe10161922495255109114117120[[#This Row],[כמות במתכון]]*VLOOKUP(Recipe10161922495255109114117120[[#This Row],[חומר גלם]],'חומרי גלם'!A:D,2,0)/VLOOKUP(Recipe10161922495255109114117120[[#This Row],[חומר גלם]],'חומרי גלם'!A:D,3,0),2) -> 7.07
A9: כללי קטן | B9: 1 | C9: =VLOOKUP(Recipe10161922495255109114117120[[#This Row],[חומר גלם]],'חומרי גלם'!A:D,4,0) -> יחידות | D9: =ROUNDUP(Recipe10161922495255109114117120[[#This Row],[כמות במתכון]]*VLOOKUP(Recipe10161922495255109114117120[[#This Row],[חומר גלם]],'חומרי גלם'!A:D,2,0)/VLOOKUP(Recipe10161922495255109114117120[[#This Row],[חומר גלם]],'חומרי גלם'!A:D,3,0),2) -> 15

Sheet אוזני המן מירי כץ פיסטוק
A1: מרכיבים | D1: =ROUNDUP(SUM(Recipe10161922495255109114117[עלות למתכון]),2) -> 42.12 | F1: עבודה | J1: כמות | O1: אריזה | Q1: =SUM(SinglePack12182124515457111113116[עלות]) -> 4.5 | T1: חזרה לתפריט
A2: חומר גלם | B2: כמות במתכון | C2: יחידת מידה | D2: עלות למתכון | F2: שעות עבודה | G2: עלות לשעת עבודה | H2: עלות עבודה | J2: כמות יחידות | K2: עלות ליחידה | O2: מוצר | P2: כמות | Q2: עלות | S2: מחיר כולל ליחדה
A3: קמח לבן מנופה | B3: 320 | C3: =VLOOKUP(Recipe10161922495255109114117[[#This Row],[חומר גלם]],'חומרי גלם'!A:D,4,0) -> גרם | D3: =ROUNDUP(Recipe10161922495255109114117[[#This Row],[כמות במתכון]]*VLOOKUP(Recipe10161922495255109114117[[#This Row],[חומר גלם]],'חומרי גלם'!A:D,2,0)/VLOOKUP(Recipe10161922495255109114117[[#This Row],[חומר גלם]],'חומרי גלם'!A:D,3,0),2) -> 2.76 | F3: 0.4 | G3: 50 | H3: =Work11172023505356110112115[[#This Row],[עלות לשעת עבודה]]*Work11172023505356110112115[[#This Row],[שעות עבודה]] -> 20 | K3: חומרים | L3: עבודה | M3: סה"כ | O3: קופסא לאינגליש מכסה גבוה | P3: 1 | Q3: =ROUNDUP(VLOOKUP(SinglePack12182124515457111113116[[#This Row],[מוצר]],אריזות!A:C,2,0)/VLOOKUP(SinglePack12182124515457111113116[[#This Row],[מוצר]],אריזות!A:C,3,0)*SinglePack12182124515457111113116[[#This Row],[כמות]],2) -> 4.5 | S3: =Q1+M4 -> 6.58
A4: אבקת סוכר | B4: 90 | C4: =VLOOKUP(Recipe10161922495255109114117[[#This Row],[חומר גלם]],'חומרי גלם'!A:D,4,0) -> גרם | D4: =ROUNDUP(Recipe10161922495255109114117[[#This Row],[כמות במתכון]]*VLOOKUP(Recipe10161922495255109114117[[#This Row],[חומר גלם]],'חומרי גלם'!A:D,2,0)/VLOOKUP(Recipe10161922495255109114117[[#This Row],[חומר גלם]],'חומרי גלם'!A:D,3,0),2) -> 0.9 | J4: 30 | K4: =ROUNDUP(D1/J4,2) -> 1.41 | L4: {=ROUNDUP(Work11172023505356110112115[עלות עבודה]/J4,2)} -> 0.67 | M4: =L4+K4 -> 2.08
A5: חמאה תנובה | B5: 200 | C5: =VLOOKUP(Recipe10161922495255109114117[[#This Row],[חומר גלם]],'חומרי גלם'!A:D,4,0) -> גרם | D5: =ROUNDUP(Recipe10161922495255109114117[[#This Row],[כמות במתכון]]*VLOOKUP(Recipe10161922495255109114117[[#This Row],[חומר גלם]],'חומרי גלם'!A:D,2,0)/VLOOKUP(Recipe10161922495255109114117[[#This Row],[חומר גלם]],'חומרי גלם'!A:D,3,0),2) -> 9
A6: ביצים L | B6: 1 | C6: =VLOOKUP(Recipe10161922495255109114117[[#This Row],[חומר גלם]],'חומרי גלם'!A:D,4,0) -> יחידות | D6: =ROUNDUP(Recipe10161922495255109114117[[#This Row],[כמות במתכון]]*VLOOKUP(Recipe10161922495255109114117[[#This Row],[חומר גלם]],'חומרי גלם'!A:D,2,0)/VLOOKUP(Recipe10161922495255109114117[[#This Row],[חומר גלם]],'חומרי גלם'!A:D,3,0),2) -> 1.17
A7: שמנת מתוקה 38% | B7: 10 | C7: =VLOOKUP(Recipe10161922495255109114117[[#This Row],[חומר גלם]],'חומרי גלם'!A:D,4,0) -> גרם | D7: =ROUNDUP(Recipe10161922495255109114117[[#This Row],[כמות במתכון]]*VLOOKUP(Recipe10161922495255109114117[[#This Row],[חומר גלם]],'חומרי גלם'!A:D,2,0)/VLOOKUP(Recipe10161922495255109114117[[#This Row],[חומר גלם]],'חומרי גלם'!A:D,3,0),2) -> 0.29
A8: ממרח spread it | B8: 40 | C8: =VLOOKUP(Recipe10161922495255109114117[[#This Row],[חומר גלם]],'חומרי גלם'!A:D,4,0) -> גרם | D8: =ROUNDUP(Recipe10161922495255109114117[[#This Row],[כמות במתכון]]*VLOOKUP(Recipe10161922495255109114117[[#This Row],[חומר גלם]],'חומרי גלם'!A:D,2,0)/VLOOKUP(Recipe10161922495255109114117[[#This Row],[חומר גלם]],'חומרי גלם'!A:D,3,0),2) -> 2.4
A9: פיסטוק | B9: 40 | C9: =VLOOKUP(Recipe10161922495255109114117[[#This Row],[חומר גלם]],'חומרי גלם'!A:D,4,0) -> גרם | D9: =ROUNDUP(Recipe10161922495255109114117[[#This Row],[כמות במתכון]]*VLOOKUP(Recipe10161922495255109114117[[#This Row],[חומר גלם]],'חומרי גלם'!A:D,2,0)/VLOOKUP(Recipe10161922495255109114117[[#This Row],[חומר גלם]],'חומרי גלם'!A:D,3,0),2) -> 5.6
A10: כללי בינוני | B10: 1 | C10: =VLOOKUP(Recipe10161922495255109114117[[#This Row],[חומר גלם]],'חומרי גלם'!A:D,4,0) -> יחידות | D10: =ROUNDUP(Recipe10161922495255109114117[[#This Row],[כמות במתכון]]*VLOOKUP(Recipe10161922495255109114117[[#This Row],[חומר גלם]],'חומרי גלם'!A:D,2,0)/VLOOKUP(Recipe10161922495255109114117[[#This Row],[חומר גלם]],'חומרי גלם'!A:D,3,0),2) -> 20

Sheet אוזני המן מירי כץ קקאו
A1: מרכיבים | D1: =ROUNDUP(SUM(Recipe10161922495255109114[עלות למתכון]),2) -> 35.65 | F1: עבודה | J1: כמות | O1: אריזה | Q1: =SUM(SinglePack12182124515457111113[עלות]) -> 4.5 | T1: חזרה לתפריט
A2: חומר גלם | B2: כמות במתכון | C2: יחידת מידה | D2: עלות למתכון | F2: שעות עבודה | G2: עלות לשעת עבודה | H2: עלות עבודה | J2: כמות יחידות | K2: עלות ליחידה | O2: מוצר | P2: כמות | Q2: עלות | S2: מחיר כולל ליחדה
A3: קמח לבן מנופה | B3: 320 | C3: =VLOOKUP(Recipe10161922495255109114[[#This Row],[חומר גלם]],'חומרי גלם'!A:D,4,0) -> גרם | D3: =ROUNDUP(Recipe10161922495255109114[[#This Row],[כמות במתכון]]*VLOOKUP(Recipe10161922495255109114[[#This Row],[חומר גלם]],'חומרי גלם'!A:D,2,0)/VLOOKUP(Recipe10161922495255109114[[#This Row],[חומר גלם]],'חומרי גלם'!A:D,3,0),2) -> 2.76 | F3: 0.4 | G3: 50 | H3: =Work11172023505356110112[[#This Row],[עלות לשעת עבודה]]*Work11172023505356110112[[#This Row],[שעות עבודה]] -> 20 | K3: חומרים | L3: עבודה | M3: סה"כ | O3: קופסא לאינגליש מכסה גבוה | P3: 1 | Q3: =ROUNDUP(VLOOKUP(SinglePack12182124515457111113[[#This Row],[מוצר]],אריזות!A:C,2,0)/VLOOKUP(SinglePack12182124515457111113[[#This Row],[מוצר]],אריזות!A:C,3,0)*SinglePack12182124515457111113[[#This Row],[כמות]],2) -> 4.5 | S3: =Q1+M4 -> 6.36
A4: אבקת סוכר | B4: 90 | C4: =VLOOKUP(Recipe10161922495255109114[[#This Row],[חומר גלם]],'חומרי גלם'!A:D,4,0) -> גרם | D4: =ROUNDUP(Recipe10161922495255109114[[#This Row],[כמות במתכון]]*VLOOKUP(Recipe10161922495255109114[[#This Row],[חומר גלם]],'חומרי גלם'!A:D,2,0)/VLOOKUP(Recipe10161922495255109114[[#This Row],[חומר גלם]],'חומרי גלם'!A:D,3,0),2) -> 0.9 | J4: 30 | K4: =ROUNDUP(D1/J4,2) -> 1.19 | L4: {=ROUNDUP(Work11172023505356110112[עלות עבודה]/J4,2)} -> 0.67 | M4: =L4+K4 -> 1.86
A5: חמאה תנובה | B5: 200 | C5: =VLOOKUP(Recipe10161922495255109114[[#This Row],[חומר גלם]],'חומרי גלם'!A:D,4,0) -> גרם | D5: =ROUNDUP(Recipe10161922495255109114[[#This Row],[כמות במתכון]]*VLOOKUP(Recipe10161922495255109114[[#This Row],[חומר גלם]],'חומרי גלם'!A:D,2,0)/VLOOKUP(Recipe10161922495255109114[[#This Row],[חומר גלם]],'חומרי גלם'!A:D,3,0),2) -> 9
A6: ביצים L | B6: 1 | C6: =VLOOKUP(Recipe10161922495255109114[[#This Row],[חומר גלם]],'חומרי גלם'!A:D,4,0) -> יחידות | D6: =ROUNDUP(Recipe10161922495255109114[[#This Row],[כמות במתכון]]*VLOOKUP(Recipe10161922495255109114[[#This Row],[חומר גלם]],'חומרי גלם'!A:D,2,0)/VLOOKUP(Recipe10161922495255109114[[#This Row],[חומר גלם]],'חומרי גלם'!A:D,3,0),2) -> 1.17
A7: שמנת מתוקה 38% | B7: 10 | C7: =VLOOKUP(Recipe10161922495255109114[[#This Row],[חומר גלם]],'חומרי גלם'!A:D,4,0) -> גרם | D7: =ROUNDUP(Recipe10161922495255109114[[#This Row],[כמות במתכון]]*VLOOKUP(Recipe10161922495255109114[[#This Row],[חומר גלם]],'חומרי גלם'!A:D,2,0)/VLOOKUP(Recipe10161922495255109114[[#This Row],[חומר גלם]],'חומרי גלם'!A:D,3,0),2) -> 0.29
A8: קקאו | B8: 35 | C8: =VLOOKUP(Recipe10161922495255109114[[#This Row],[חומר גלם]],'חומרי גלם'!A:D,4,0) -> גרם | D8: =ROUNDUP(Recipe10161922495255109114[[#This Row],[כמות במתכון]]*VLOOKUP(Recipe10161922495255109114[[#This Row],[חומר גלם]],'חומרי גלם'!A:D,2,0)/VLOOKUP(Recipe10161922495255109114[[#This Row],[חומר גלם]],'חומרי גלם'!A:D,3,0),2) -> 1.53
A9: כללי בינוני | B9: 1 | C9: =VLOOKUP(Recipe10161922495255109114[[#This Row],[חומר גלם]],'חומרי גלם'!A:D,4,0) -> יחידות | D9: =ROUNDUP(Recipe10161922495255109114[[#This Row],[כמות במתכון]]*VLOOKUP(Recipe10161922495255109114[[#This Row],[חומר גלם]],'חומרי גלם'!A:D,2,0)/VLOOKUP(Recipe10161922495255109114[[#This Row],[חומר גלם]],'חומרי גלם'!A:D,3,0),2) -> 20

Sheet אוזני המן מירי כץ וניל
A1: מרכיבים | D1: =ROUNDUP(SUM(Recipe10161922495255109[עלות למתכון]),2) -> 34.42 | F1: עבודה | J1: כמות | O1: אריזה | Q1: =SUM(SinglePack12182124515457111[עלות]) -> 4.5 | T1: חזרה לתפריט
A2: חומר גלם | B2: כמות במתכון | C2: יחידת מידה | D2: עלות למתכון | F2: שעות עבודה | G2: עלות לשעת עבודה | H2: עלות עבודה | J2: כמות יחידות | K2: עלות ליחידה | O2: מוצר | P2: כמות | Q2: עלות | S2: מחיר כולל ליחדה
A3: קמח לבן מנופה | B3: 350 | C3: =VLOOKUP(Recipe10161922495255109[[#This Row],[חומר גלם]],'חומרי גלם'!A:D,4,0) -> גרם | D3: =ROUNDUP(Recipe10161922495255109[[#This Row],[כמות במתכון]]*VLOOKUP(Recipe10161922495255109[[#This Row],[חומר גלם]],'חומרי גלם'!A:D,2,0)/VLOOKUP(Recipe10161922495255109[[#This Row],[חומר גלם]],'חומרי גלם'!A:D,3,0),2) -> 3.01 | F3: 0.4 | G3: 50 | H3: =Work11172023505356110[[#This Row],[עלות לשעת עבודה]]*Work11172023505356110[[#This Row],[שעות עבודה]] -> 20 | K3: חומרים | L3: עבודה | M3: סה"כ | O3: קופסא לאינגליש מכסה גבוה | P3: 1 | Q3: =ROUNDUP(VLOOKUP(SinglePack12182124515457111[[#This Row],[מוצר]],אריזות!A:C,2,0)/VLOOKUP(SinglePack12182124515457111[[#This Row],[מוצר]],אריזות!A:C,3,0)*SinglePack12182124515457111[[#This Row],[כמות]],2) -> 4.5 | S3: =Q1+M4 -> 6.32
A4: אבקת סוכר | B4: 95 | C4: =VLOOKUP(Recipe10161922495255109[[#This Row],[חומר גלם]],'חומרי גלם'!A:D,4,0) -> גרם | D4: =ROUNDUP(Recipe10161922495255109[[#This Row],[כמות במתכון]]*VLOOKUP(Recipe10161922495255109[[#This Row],[חומר גלם]],'חומרי גלם'!A:D,2,0)/VLOOKUP(Recipe10161922495255109[[#This Row],[חומר גלם]],'חומרי גלם'!A:D,3,0),2) -> 0.95 | J4: 30 | K4: =ROUNDUP(D1/J4,2) -> 1.15 | L4: {=ROUNDUP(Work11172023505356110[עלות עבודה]/J4,2)} -> 0.67 | M4: =L4+K4 -> 1.82
A5: חמאה תנובה | B5: 200 | C5: =VLOOKUP(Recipe10161922495255109[[#This Row],[חומר גלם]],'חומרי גלם'!A:D,4,0) -> גרם | D5: =ROUNDUP(Recipe10161922495255109[[#This Row],[כמות במתכון]]*VLOOKUP(Recipe10161922495255109[[#This Row],[חומר גלם]],'חומרי גלם'!A:D,2,0)/VLOOKUP(Recipe10161922495255109[[#This Row],[חומר גלם]],'חומרי גלם'!A:D,3,0),2) -> 9
A6: ביצים L | B6: 1 | C6: =VLOOKUP(Recipe10161922495255109[[#This Row],[חומר גלם]],'חומרי גלם'!A:D,4,0) -> יחידות | D6: =ROUNDUP(Recipe10161922495255109[[#This Row],[כמות במתכון]]*VLOOKUP(Recipe10161922495255109[[#This Row],[חומר גלם]],'חומרי גלם'!A:D,2,0)/VLOOKUP(Recipe10161922495255109[[#This Row],[חומר גלם]],'חומרי גלם'!A:D,3,0),2) -> 1.17
A7: שמנת מתוקה 38% | B7: 10 | C7: =VLOOKUP(Recipe10161922495255109[[#This Row],[חומר גלם]],'חומרי גלם'!A:D,4,0) -> גרם | D7: =ROUNDUP(Recipe10161922495255109[[#This Row],[כמות במתכון]]*VLOOKUP(Recipe10161922495255109[[#This Row],[חומר גלם]],'חומרי גלם'!A:D,2,0)/VLOOKUP(Recipe10161922495255109[[#This Row],[חומר גלם]],'חומרי גלם'!A:D,3,0),2) -> 0.29
A8: כללי בינוני | B8: 1 | C8: =VLOOKUP(Recipe10161922495255109[[#This Row],[חומר גלם]],'חומרי גלם'!A:D,4,0) -> יחידות | D8: =ROUNDUP(Recipe10161922495255109[[#This Row],[כמות במתכון]]*VLOOKUP(Recipe10161922495255109[[#This Row],[חומר גלם]],'חומרי גלם'!A:D,2,0)/VLOOKUP(Recipe10161922495255109[[#This Row],[חומר גלם]],'חומרי גלם'!A:D,3,0),2) -> 20

Sheet עוגת שוקולד בלי ביצים
A1: מרכיבים | D1: =ROUNDUP(SUM(Recipe1058616467707376798285919497100103106[עלות למתכון]),2) -> 33.69 | F1: עבודה | J1: כמות | O1: אריזה | Q1: =SUM(SinglePack1260636669727578818487939699102105108[עלות]) -> 3.5 | T1: חזרה לתפריט
A2: חומר גלם | B2: כמות במתכון | C2: יחידת מידה | D2: עלות למתכון | F2: שעות עבודה | G2: עלות לשעת עבודה | H2: עלות עבודה | J2: כמות יחידות | K2: עלות ליחידה | O2: מוצר | P2: כמות | Q2: עלות | S2: מחיר כולל ליחדה
A3: קמח לבן מנופה | B3: 575 | C3: =VLOOKUP(Recipe1058616467707376798285919497100103106[[#This Row],[חומר גלם]],'חומרי גלם'!A:D,4,0) -> גרם | D3: =ROUNDUP(Recipe1058616467707376798285919497100103106[[#This Row],[כמות במתכון]]*VLOOKUP(Recipe1058616467707376798285919497100103106[[#This Row],[חומר גלם]],'חומרי גלם'!A:D,2,0)/VLOOKUP(Recipe1058616467707376798285919497100103106[[#This Row],[חומר גלם]],'חומרי גלם'!A:D,3,0),2) -> 4.95 | F3: 0.4 | G3: 100 | H3: =Work1159626568717477808386929598101104107[[#This Row],[עלות לשעת עבודה]]*Work1159626568717477808386929598101104107[[#This Row],[שעות עבודה]] -> 40 | K3: חומרים | L3: עבודה | M3: סה"כ | O3: קריסטל לב קוטר 16 | P3: 1 | Q3: =ROUNDUP(VLOOKUP(SinglePack1260636669727578818487939699102105108[[#This Row],[מוצר]],אריזות!A:C,2,0)/VLOOKUP(SinglePack1260636669727578818487939699102105108[[#This Row],[מוצר]],אריזות!A:C,3,0)*SinglePack1260636669727578818487939699102105108[[#This Row],[כמות]],2) -> 3.5 | S3: =Q1+M4 -> 77.19
A4: סוכר לבן | B4: 600 | C4: =VLOOKUP(Recipe1058616467707376798285919497100103106[[#This Row],[חומר גלם]],'חומרי גלם'!A:D,4,0) -> גרם | D4: =ROUNDUP(Recipe1058616467707376798285919497100103106[[#This Row],[כמות במתכון]]*VLOOKUP(Recipe1058616467707376798285919497100103106[[#This Row],[חומר גלם]],'חומרי גלם'!A:D,2,0)/VLOOKUP(Recipe1058616467707376798285919497100103106[[#This Row],[חומר גלם]],'חומרי גלם'!A:D,3,0),2) -> 3.12 | J4: 1 | K4: =ROUNDUP(D1/J4,2) -> 33.69 | L4: {=ROUNDUP(Work1159626568717477808386929598101104107[עלות עבודה]/J4,2)} -> 40 | M4: =L4+K4 -> 73.69
A5: חומץ | B5: 30 | C5: =VLOOKUP(Recipe1058616467707376798285919497100103106[[#This Row],[חומר גלם]],'חומרי גלם'!A:D,4,0) -> מיליליטר | D5: =ROUNDUP(Recipe1058616467707376798285919497100103106[[#This Row],[כמות במתכון]]*VLOOKUP(Recipe1058616467707376798285919497100103106[[#This Row],[חומר גלם]],'חומרי גלם'!A:D,2,0)/VLOOKUP(Recipe1058616467707376798285919497100103106[[#This Row],[חומר גלם]],'חומרי גלם'!A:D,3,0),2) -> 0.21
A6: שמן | B6: 265 | C6: =VLOOKUP(Recipe1058616467707376798285919497100103106[[#This Row],[חומר גלם]],'חומרי גלם'!A:D,4,0) -> מיליליטר | D6: =ROUNDUP(Recipe1058616467707376798285919497100103106[[#This Row],[כמות במתכון]]*VLOOKUP(Recipe1058616467707376798285919497100103106[[#This Row],[חומר גלם]],'חומרי גלם'!A:D,2,0)/VLOOKUP(Recipe1058616467707376798285919497100103106[[#This Row],[חומר גלם]],'חומרי גלם'!A:D,3,0),2) -> 3.95
